Traceback (most recent call last):
  File "/Users/knf792/miniconda3/envs/nlp-course/lib/python3.10/site-packages/jupyter_cache/executors/utils.py", line 51, in single_nb_execution
    executenb(
  File "/Users/knf792/miniconda3/envs/nlp-course/lib/python3.10/site-packages/nbclient/client.py", line 1204, in execute
    return NotebookClient(nb=nb, resources=resources, km=km, **kwargs).execute()
  File "/Users/knf792/miniconda3/envs/nlp-course/lib/python3.10/site-packages/nbclient/util.py", line 84, in wrapped
    return just_run(coro(*args, **kwargs))
  File "/Users/knf792/miniconda3/envs/nlp-course/lib/python3.10/site-packages/nbclient/util.py", line 62, in just_run
    return loop.run_until_complete(coro)
  File "/Users/knf792/miniconda3/envs/nlp-course/lib/python3.10/asyncio/base_events.py", line 646, in run_until_complete
    return future.result()
  File "/Users/knf792/miniconda3/envs/nlp-course/lib/python3.10/site-packages/nbclient/client.py", line 663, in async_execute
    await self.async_execute_cell(
  File "/Users/knf792/miniconda3/envs/nlp-course/lib/python3.10/site-packages/nbclient/client.py", line 965, in async_execute_cell
    await self._check_raise_for_error(cell, cell_index, exec_reply)
  File "/Users/knf792/miniconda3/envs/nlp-course/lib/python3.10/site-packages/nbclient/client.py", line 862, in _check_raise_for_error
    raise CellExecutionError.from_cell_and_msg(cell, exec_reply_content)
nbclient.exceptions.CellExecutionError: An error occurred while executing the following cell:
------------------
conllu = """
# ID	FORM	LEMMA	UPOS	XPOS	FEATS	HEAD	DEPREL	DEPS	MISC
1	I	_	_	_	_	2	nsubj	_	_
2	saw	_	_	_	_	0	root	_	_
3	the	_	_	_	_	4	det	_	_
4	star	_	_	_	_	2	dobj	_	_
5	with	_	_	_	_	7	case	_	_
6	the	_	_	_	_	7	det	_	_
7	telescope	_	_	_	_	2	obl	_	_
"""
# display(HTML(pd.read_csv(StringIO(conllu), sep="\t").to_html(index=False)))
arcs, tokens = to_displacy_graph(*load_arcs_tokens(conllu))
render_displacy(arcs, tokens,"2400px")
------------------

[0;31m---------------------------------------------------------------------------[0m
[0;31mNameError[0m                                 Traceback (most recent call last)
Input [0;32mIn [4][0m, in [0;36m<cell line: 12>[0;34m()[0m
[1;32m      1[0m conllu [38;5;241m=[39m [38;5;124m"""[39m
[1;32m      2[0m [38;5;124m# ID	FORM	LEMMA	UPOS	XPOS	FEATS	HEAD	DEPREL	DEPS	MISC[39m
[1;32m      3[0m [38;5;124m1	I	_	_	_	_	2	nsubj	_	_[39m
[0;32m   (...)[0m
[1;32m      9[0m [38;5;124m7	telescope	_	_	_	_	2	obl	_	_[39m
[1;32m     10[0m [38;5;124m"""[39m
[1;32m     11[0m [38;5;66;03m# display(HTML(pd.read_csv(StringIO(conllu), sep="\t").to_html(index=False)))[39;00m
[0;32m---> 12[0m arcs, tokens [38;5;241m=[39m [43mto_displacy_graph[49m([38;5;241m*[39mload_arcs_tokens(conllu))
[1;32m     13[0m render_displacy(arcs, tokens,[38;5;124m"[39m[38;5;124m2400px[39m[38;5;124m"[39m)

[0;31mNameError[0m: name 'to_displacy_graph' is not defined
NameError: name 'to_displacy_graph' is not defined

